<?xml version="1.0" ?>
<!-- =================================================================================== -->
<!-- |    This document was autogenerated by xacro from surgical_robot.urdf.xacro      | -->
<!-- |    EDITING THIS FILE BY HAND IS NOT RECOMMENDED                                 | -->
<!-- =================================================================================== -->
<robot name="surgical_robot">
  <link name="dummy_link"/>
  <link name="base_link">
    <inertial>
      <origin rpy="0 0 0" xyz="1.4888E-35 -1.7353E-15 0.49949"/>
      <mass value="196.14"/>
      <inertia ixx="19.381" ixy="-2.5846E-34" ixz="-4.859E-32" iyy="19.381" iyz="4.7118E-14" izz="6.1357"/>
    </inertial>
    <visual>
      <origin rpy="0 0 0" xyz="0 0 0"/>
      <geometry>
        <mesh filename="package://surgical_robot/meshes/base_link.STL"/>
      </geometry>
      <material name="">
        <color rgba="0.79216 0.81961 0.93333 1"/>
      </material>
    </visual>
    <collision>
      <origin rpy="0 0 0" xyz="0 0 0"/>
      <geometry>
        <mesh filename="package://surgical_robot/meshes/base_link.STL"/>
      </geometry>
    </collision>
  </link>
  <joint name="dummy_joint" type="fixed">
    <origin rpy="0 0 0" xyz="0 0 0"/>
    <parent link="dummy_link"/>
    <child link="base_link"/>
  </joint>
  <link name="link_1">
    <inertial>
      <origin rpy="0 0 0" xyz="2.891E-09 0.0039396 0.072722"/>
      <mass value="3.1124"/>
      <inertia ixx="0.012618" ixy="-1.3877E-09" ixz="-1.601E-10" iyy="0.012079" iyz="-0.00021066" izz="0.0095751"/>
    </inertial>
    <visual>
      <origin rpy="0 0 0" xyz="0 0 0"/>
      <geometry>
        <mesh filename="package://surgical_robot/meshes/link_1.STL"/>
      </geometry>
      <material name="">
        <color rgba="0.61569 0 0 1"/>
      </material>
    </visual>
    <collision>
      <origin rpy="0 0 0" xyz="0 0 0"/>
      <geometry>
        <mesh filename="package://surgical_robot/meshes/link_1.STL"/>
      </geometry>
    </collision>
  </link>
  <joint name="joint_1" type="revolute">
    <origin rpy="0 0 0" xyz="0 0 1"/>
    <parent link="base_link"/>
    <child link="link_1"/>
    <axis xyz="0 0 1"/>
    <limit effort="1" lower="-6.28" upper="6.28" velocity="1"/>
  </joint>
  <link name="link_2">
    <inertial>
      <origin rpy="0 0 0" xyz="6.6644E-08 -0.25396 0.16786"/>
      <mass value="8.8287"/>
      <inertia ixx="0.51621" ixy="-6.1924E-08" ixz="1.605E-08" iyy="0.022298" iyz="0.0072393" izz="0.5119"/>
    </inertial>
    <visual>
      <origin rpy="0 0 0" xyz="0 0 0"/>
      <geometry>
        <mesh filename="package://surgical_robot/meshes/link_2.STL"/>
      </geometry>
      <material name="">
        <color rgba="1 1 1 1"/>
      </material>
    </visual>
    <collision>
      <origin rpy="0 0 0" xyz="0 0 0"/>
      <geometry>
        <mesh filename="package://surgical_robot/meshes/link_2.STL"/>
      </geometry>
    </collision>
  </link>
  <joint name="joint_2" type="revolute">
    <origin rpy="-1.5708 0 0" xyz="0 0 0.0899"/>
    <parent link="link_1"/>
    <child link="link_2"/>
    <axis xyz="0 0 -1"/>
    <limit effort="1" lower="-6.28" upper="6.28" velocity="1"/>
  </joint>
  <link name="link_3">
    <inertial>
      <origin rpy="0 0 0" xyz="2.2953E-07 0.26987 0.12548"/>
      <mass value="4.1976"/>
      <inertia ixx="0.18328" ixy="3.1249E-08" ixz="1.0783E-08" iyy="0.0046038" iyz="-0.00088442" izz="0.1832"/>
    </inertial>
    <visual>
      <origin rpy="0 0 0" xyz="0 0 0"/>
      <geometry>
        <mesh filename="package://surgical_robot/meshes/link_3.STL"/>
      </geometry>
      <material name="">
        <color rgba="1 1 1 1"/>
      </material>
    </visual>
    <collision>
      <origin rpy="0 0 0" xyz="0 0 0"/>
      <geometry>
        <mesh filename="package://surgical_robot/meshes/link_3.STL"/>
      </geometry>
    </collision>
  </link>
  <joint name="joint_3" type="revolute">
    <origin rpy="3.1416 0 0" xyz="0 -0.61288 0.176"/>
    <parent link="link_2"/>
    <child link="link_3"/>
    <axis xyz="0 0 1"/>
    <limit effort="1" lower="-6.28" upper="6.28" velocity="1"/>
  </joint>
  <link name="link_4">
    <inertial>
      <origin rpy="0 0 0" xyz="0.047464 -0.0066476 0.1067"/>
      <mass value="0.85088"/>
      <inertia ixx="0.001427" ixy="8.7678E-09" ixz="1.7801E-08" iyy="0.0012319" iyz="8.631E-05" izz="0.0011597"/>
    </inertial>
    <visual>
      <origin rpy="0 0 0" xyz="0 0 0"/>
      <geometry>
        <mesh filename="package://surgical_robot/meshes/link_4.STL"/>
      </geometry>
      <material name="">
        <color rgba="1 1 1 1"/>
      </material>
    </visual>
    <collision>
      <origin rpy="0 0 0" xyz="0 0 0"/>
      <geometry>
        <mesh filename="package://surgical_robot/meshes/link_4.STL"/>
      </geometry>
    </collision>
  </link>
  <joint name="joint_4" type="revolute">
    <origin rpy="-3.1416 0 0" xyz="-0.047464 0.57336 0.12966"/>
    <parent link="link_3"/>
    <child link="link_4"/>
    <axis xyz="0 0 1"/>
    <limit effort="1" lower="-6.28" upper="6.28" velocity="1"/>
  </joint>
  <link name="link_5">
    <inertial>
      <origin rpy="0 0 0" xyz="5.3474E-09 0.0082924 0.10956"/>
      <mass value="0.7955"/>
      <inertia ixx="0.0012553" ixy="-3.0646E-10" ixz="-4.4927E-10" iyy="0.0010475" iyz="-4.0434E-05" izz="0.0011051"/>
    </inertial>
    <visual>
      <origin rpy="0 0 0" xyz="0 0 0"/>
      <geometry>
        <mesh filename="package://surgical_robot/meshes/link_5.STL"/>
      </geometry>
      <material name="">
        <color rgba="1 1 1 1"/>
      </material>
    </visual>
    <collision>
      <origin rpy="0 0 0" xyz="0 0 0"/>
      <geometry>
        <mesh filename="package://surgical_robot/meshes/link_5.STL"/>
      </geometry>
    </collision>
  </link>
  <joint name="joint_5" type="revolute">
    <origin rpy="1.5708 0 0" xyz="0.047464 0.001736 0.11755"/>
    <parent link="link_4"/>
    <child link="link_5"/>
    <axis xyz="0 0 -1"/>
    <limit effort="1" lower="-6.28" upper="6.28" velocity="1"/>
  </joint>
  <link name="link_6">
    <inertial>
      <origin rpy="0 0 0" xyz="0.00039972 0 0.1318"/>
      <mass value="0.94482"/>
      <inertia ixx="0.0023254" ixy="7.8583E-20" ixz="-5.3166E-06" iyy="0.0023254" iyz="-1.0398E-18" izz="0.0010002"/>
    </inertial>
    <visual>
      <origin rpy="0 0 0" xyz="0 0 0"/>
      <geometry>
        <mesh filename="package://surgical_robot/meshes/link_6.STL"/>
      </geometry>
      <material name="">
        <color rgba="1 1 1 1"/>
      </material>
    </visual>
    <collision>
      <origin rpy="0 0 0" xyz="0 0 0"/>
      <geometry>
        <mesh filename="package://surgical_robot/meshes/link_6.STL"/>
      </geometry>
    </collision>
  </link>
  <joint name="joint_6" type="revolute">
    <origin rpy="-1.5708 0 0" xyz="0 0 0.1157"/>
    <parent link="link_5"/>
    <child link="link_6"/>
    <axis xyz="0 0 1"/>
    <limit effort="1" lower="-6.28" upper="6.28" velocity="1"/>
  </joint>
  <link name="camera_link">
    <inertial>
      <origin rpy="0 0 0" xyz="-1.7347E-18 0 -0.02"/>
      <mass value="0.064"/>
      <inertia ixx="1.7067E-05" ixy="-1.2117E-21" ixz="1.3431E-21" iyy="1.7067E-05" iyz="-1.7324E-21" izz="1.7067E-05"/>
    </inertial>
    <visual>
      <origin rpy="0 0 0" xyz="0 0 0"/>
      <geometry>
        <mesh filename="package://surgical_robot/meshes/camera_link.STL"/>
      </geometry>
      <material name="">
        <color rgba="0.79216 0.81961 0.93333 1"/>
      </material>
    </visual>
    <collision>
      <origin rpy="0 0 0" xyz="0 0 0"/>
      <geometry>
        <mesh filename="package://surgical_robot/meshes/camera_link.STL"/>
      </geometry>
    </collision>
  </link>
  <joint name="camera_joint" type="fixed">
    <origin rpy="0 0 0" xyz="0.010115 -0.0675 0.1325"/>
    <parent link="link_6"/>
    <child link="camera_link"/>
    <axis xyz="0 0 0"/>
  </joint>
  <gazebo reference="camera_link">
    <sensor name="camera_sensor" type="camera">
      <camera>
        <horizontal_fov>1.047</horizontal_fov>
        <!-- Field of view (in radians) -->
        <image>
          <width>640</width>
          <height>480</height>
          <format>R8G8B8</format>
          <!-- RGB8 format -->
        </image>
        <clip>
          <near>0.01</near>
          <far>100</far>
        </clip>
      </camera>
      <plugin filename="libgazebo_ros_camera.so" name="camera_controller">
        <ros>
          <namespace>/camera</namespace>
          <!-- Namespace for topics -->
          <argument>--ros-args</argument>
        </ros>
        <update_rate>30.0</update_rate>
        <image_topic_name>image_raw</image_topic_name>
        <camera_info_topic_name>camera_info</camera_info_topic_name>
      </plugin>
    </sensor>
  </gazebo>
  <gazebo>
    <plugin filename="libgazebo_ros_vacuum_gripper.so" name="vacuum_gripper">
      <!-- This part can be commented out if not required -->
      <ros>
        <remapping>grasping:=/grasping</remapping>
      </ros>
      <!-- Link associated with gripper -->
      <link_name>link_6</link_name>
      <!-- Max distance to attract entities -->
      <max_distance>10.0</max_distance>
      <!-- List of entities to be not attracted by the gripper -->
      <fixed>ground_plane</fixed>
      <fixed>wall</fixed>
    </plugin>
  </gazebo>
  <ros2_control name="GazeboSystem" type="system">
    <hardware>
      <plugin>gazebo_ros2_control/GazeboSystem</plugin>
    </hardware>
    <joint name="joint_1">
      <command_interface name="position">
        <param name="min">-3.14</param>
        <param name="max">3.14</param>
      </command_interface>
      <state_interface name="position"/>
      <state_interface name="velocity"/>
      <state_interface name="effort"/>
    </joint>
    <joint name="joint_2">
      <command_interface name="position">
        <param name="min">-3.14</param>
        <param name="max">3.14</param>
      </command_interface>
      <state_interface name="position"/>
      <state_interface name="velocity"/>
      <state_interface name="effort"/>
    </joint>
    <joint name="joint_3">
      <command_interface name="position">
        <param name="min">-3.14</param>
        <param name="max">3.14</param>
      </command_interface>
      <state_interface name="position"/>
      <state_interface name="velocity"/>
      <state_interface name="effort"/>
    </joint>
    <joint name="joint_4">
      <command_interface name="position">
        <param name="min">-3.14</param>
        <param name="max">3.14</param>
      </command_interface>
      <state_interface name="position"/>
      <state_interface name="velocity"/>
      <state_interface name="effort"/>
    </joint>
    <joint name="joint_5">
      <command_interface name="position">
        <param name="min">-3.14</param>
        <param name="max">3.14</param>
      </command_interface>
      <state_interface name="position"/>
      <state_interface name="velocity"/>
      <state_interface name="effort"/>
    </joint>
    <joint name="joint_6">
      <command_interface name="position">
        <param name="min">-3.14</param>
        <param name="max">3.14</param>
      </command_interface>
      <state_interface name="position"/>
      <state_interface name="velocity"/>
      <state_interface name="effort"/>
    </joint>
  </ros2_control>
  <!-- Gazebo Plugins-->
  <gazebo>
    <plugin filename="libgz_ros2_control.so" name="ros2_control">
      <ros2_control>
        <param name="robot_description">/robot_description</param>
      </ros2_control>
    </plugin>
  </gazebo>
</robot>
